"#dig Multilayer test, upward",,
r,d,d
d,,d
d,d,d
#<,,
d,d,d
d,r,d
d,d,d
#<,,
d,d,d
d,,d
d,d,r
