#dig Multilayer test,,
r,d,d
d,,d
d,d,d
#>,,
d,d,d
d,r,d
d,d,d
#>,,
d,d,d
d,,d
d,d,r
